# 异常对程序的影响
在程序正常的时候，程序会按照既定的顺序从头到尾执行/但是出现了错误之后，就会在中途中断程序的执行，比如`System.out.println("计算："+(10/0))`，那么就会在此处中断，但这并不是一个致命的错误，所以即使发生一点小错误，程序也要继续往下执行

# 处理异常
Java进行异常的处理，可以使用try、catch、finally这几个关键字来完成，其基本的处理结构如下：
```
try{
	//可能出现异常的语句
}catch(异常处理 异常对象){
	//异常处理
}catch(异常处理 异常对象){
	//异常处理
}catch(异常处理 异常对象){
	//异常处理
}finally{
	//不管异常是否处理都要执行
}
```
使用组合为：try...catch、try...catch...finally、try...finally。
### 范例：处理异常
```
public class Test{
	public static void main(String[] args){
    	System.out.println("【1】*****程序开始执行*****");
        try{
        	System.out.println("【2】数学计算："+(10/0));
        }catch(ArithmeticException e){
        	e.printStackTrace();//输出异常信息
        }finally{
        	System.out.println("程序执行完成")
        }
    }
}
```

# 处理多个异常
该程序需要处理多个异常。包括：
1.执行的时候没有输入初始化参数
2.输入的参数不是数字
3.被除数为0
```
publcC class Test{
	public static void main(STring args[]){
    	System.out.println("计算 x/y");
        try{
        	int x = Integer.parseInt(args[0]);
            int y = Integer.parseInt(args[1]);
            System.out.println("计算结果："+(x/y));
        }catch(ArithmeticException e){
        	e.printStackTrace();
        }catch(NumberFormatException e){
        	e.printStackTrace();
        }catch(ArrayIndexOutOfBoundException e){
        	w.printStackTrace();
        }
    }
}
```

# 异常处理流程
一般异常的处理流程为
1.如果没有try，catch那么交给JVM默认执行
2.包含在try中的代码出现错误随时被捕获
3.捕获出的错误在对应的catch中进行输出，但也可能捕获不到，因为没有对应的错误
4.最后进入finally执行，如果到达finally错误仍然未被捕捉，那么就交给JVM默认处理。

也可以直接:
```
catch(Exception e){
	e.printStackTrace();
}
```
但是这样也会出现问题，都用Exception，输出的描述信息不明确。所以在异常捕获的时候，要把**捕获范围小的异常放在捕获范围大的异常之前**，让调试信息更为明确。

# throws关键字
通过之前的程序可以发现，在执行程序的过程之中可能出现异常，但是如果在定义方法的时候申明了可能出现的异常，就会好很多。可以在方法的申明上使用throws进行异常的标注。
```
class Fun{
	public static void calc(int x,int y) throws Exception{
    	System.out.println(x/y);
    }
}
```
也可以使用主方法对异常继续向上抛出，交由JVM处理
```
public class Test{
	public static void main(String[] args) throws Exception{
    	Fun.calc(10,2);
    }
}
```
# throw关键字
与throws对应的是throw关键字，此关键字的主要作用在于进行手工进行异常的抛出，就是手工产生一个异常类的实例化对象，并且进行异常的抛出处理。
### 范例：throw的使用
```
public class JavaDemo{
	public static void main(String args[]) throw Exception{
    	try{//不再由系统捕捉
        	throw new Exception("自己抛出的异常");
        }catch(Exception e){
        	e.printStackTrace();
        }
    }
}
```
### 面试题：throw与throws区别
- throw:实在代码块中使用的，主要是手工进行异常对象的抛出
- throws：是在方法定义上使用的，表示将此方法可能产生的异常明确告诉给调用处，由调用处进行处理

# 异常处理的标准格式
现在定义一个可以实现除法计算的方法
```
class Calc {
	
    public static int fun(int x,int y) throws Exception{
        Sysytem.out.println("***计算开始***");
        int temp = 0;
        try{
            temp = x/y;
        }cache(Exception e){
        	throws e;//向上抛出
        }finally{
        	Sysytem.out.println("***计算结束***");
        }
        
        return temp;
    } 

}
```
上面就是基本结构，try,chach，finally都有

# RuntimeException
前面说到当一个方法throws Exception的时候，是强制要抛出异常的，只有包裹在try cache中才会不报异常。但是有的函数加上了throws Exception之后也不会强制性的抛出异常，这就和RuntimeException有关。

### 面试题：RuntimeException与Exception的区别？
- RuntimeException是Exception的子类
- RuntimeException的异常可以不用进行强制性的处理，而Exception异常必须强制性处理

# 自定义异常类
自定义异常一般继承Exceptiion和RuntimeException
```
class BombException extends Exception{
	public BombException(String msg){
    	super(msg);
    }
}
class Food{
	public static void eat(int num) throws BombException{
    	if(num > 10){
        	throw new BombException("吃太多了，肚子爆炸了")
        }else{
        	System.out.println("正常开始吃。。。。");
        }
    }
}
```

# assert关键字
从JDK1.4开始有一个断言的功能，确定代码执行到某一行之后一定是所期待的结果。但是期待的结果也会出现一定的偏差，而这种偏差不应该影响程序的执行。就像是一个人给你一个最终建议，但这个建议可能并不准确

### 举例：断言：
```
public class JavaDemo{
	public static void main(String args[]) throws Exception{
    	int x = 10;
        //中间会经过许多x变量的操作步骤
        assert x == 100 : "x的内容不是100"；
        System.out.println(x);
    }
}
```
该程序只用在程序执行的时候加上-ea这个参数，才能启用断言，才会出现结果。

